From c591c1169984e1b9013293b501e324eba053e833 Mon Sep 17 00:00:00 2001
From: Dirk Groeneveld <dirkg@allenai.org>
Date: Fri, 12 Nov 2021 14:08:34 -0800
Subject: [PATCH 5/5] HF now raises ValueError (#5464)

---
 tests/common/push_to_hub_test.py | 2 +-
 1 file changed, 1 insertion(+), 1 deletion(-)

diff --git a/tests/common/push_to_hub_test.py b/tests/common/push_to_hub_test.py
index 29db7519..86f1fccc 100644
--- a/tests/common/push_to_hub_test.py
+++ b/tests/common/push_to_hub_test.py
@@ -136,7 +136,7 @@ class TestPushToHub(AllenNlpTestCase):
     @with_staging_testing
     def test_push_to_hub_fails_with_invalid_token(self):
         serialization_dir = self.FIXTURES_ROOT / "simple_tagger" / "serialization"
-        with pytest.raises(requests.exceptions.HTTPError):
+        with pytest.raises(ValueError):
             push_to_hf(
                 repo_name=REPO_NAME,
                 serialization_dir=serialization_dir,
-- 
2.32.0.windows.2

